2025-03-08 13:05:24,887 - INFO - API Gatherer initialized successfully
2025-03-08 13:05:24,887 - INFO - Intel X client initialized successfully
2025-03-08 13:05:24,887 - INFO - ====== WebDriver manager ======
2025-03-08 13:05:24,960 - INFO - Get LATEST chromedriver version for google-chrome
2025-03-08 13:05:26,018 - INFO - Get LATEST chromedriver version for google-chrome
2025-03-08 13:05:27,254 - INFO - There is no [linux64] chromedriver "131.0.6778.264" for browser google-chrome "131.0.6778" in cache
2025-03-08 13:05:27,254 - INFO - Get LATEST chromedriver version for google-chrome
2025-03-08 13:05:28,927 - INFO - WebDriver version 131.0.6778.264 selected
2025-03-08 13:05:28,930 - INFO - Modern chrome version https://storage.googleapis.com/chrome-for-testing-public/131.0.6778.264/linux64/chromedriver-linux64.zip
2025-03-08 13:05:28,930 - INFO - About to download new driver from https://storage.googleapis.com/chrome-for-testing-public/131.0.6778.264/linux64/chromedriver-linux64.zip
2025-03-08 13:05:37,576 - INFO - Driver downloading response is 200
2025-03-08 13:05:46,258 - INFO - Get LATEST chromedriver version for google-chrome
2025-03-08 13:05:46,732 - INFO - Driver has been saved in cache [/home/prx00/.wdm/drivers/chromedriver/linux64/131.0.6778.264]
2025-03-08 13:05:47,419 - INFO - Chrome WebDriver initialized successfully
2025-03-08 13:05:47,419 - INFO - OSINT Gatherer initialized successfully
2025-03-08 13:05:47,424 - ERROR - Tor authentication failed: Authentication failed: unable to read '/run/tor/control.authcookie' ([Errno 13] Permission denied: '/run/tor/control.authcookie')
2025-03-08 13:05:47,425 - INFO - Error while receiving a control message (SocketClosed): empty socket content
2025-03-08 13:05:47,425 - INFO - Error while receiving a control message (SocketClosed): empty socket content
2025-03-08 13:05:47,427 - ERROR - Tor authentication retry failed: Authentication failed: unable to read '/run/tor/control.authcookie' ([Errno 13] Permission denied: '/run/tor/control.authcookie')
2025-03-08 13:05:47,427 - ERROR - Failed to setup Tor: Authentication failed: unable to read '/run/tor/control.authcookie' ([Errno 13] Permission denied: '/run/tor/control.authcookie')
2025-03-08 13:05:47,427 - ERROR - Failed to initialize Dark Web Monitor: Authentication failed: unable to read '/run/tor/control.authcookie' ([Errno 13] Permission denied: '/run/tor/control.authcookie')
Traceback (most recent call last):
  File "/home/prx00/spyeyev1/osunt/spyeye/lib/python3.11/site-packages/stem/connection.py", line 1103, in _read_cookie
    with open(cookie_path, 'rb', 0) as f:
         ^^^^^^^^^^^^^^^^^^^^^^^^^^
PermissionError: [Errno 13] Permission denied: '/run/tor/control.authcookie'

During handling of the above exception, another exception occurred:

Traceback (most recent call last):
  File "/home/prx00/spyeyev1/osunt/darkweb_monitor.py", line 91, in _setup_tor
    self.tor_controller.authenticate()
  File "/home/prx00/spyeyev1/osunt/spyeye/lib/python3.11/site-packages/stem/control.py", line 1112, in authenticate
    stem.connection.authenticate(self, *args, **kwargs)
  File "/home/prx00/spyeyev1/osunt/spyeye/lib/python3.11/site-packages/stem/connection.py", line 629, in authenticate
    raise auth_exc
  File "/home/prx00/spyeyev1/osunt/spyeye/lib/python3.11/site-packages/stem/connection.py", line 591, in authenticate
    authenticate_safecookie(controller, cookie_path, False)
  File "/home/prx00/spyeyev1/osunt/spyeye/lib/python3.11/site-packages/stem/connection.py", line 904, in authenticate_safecookie
    cookie_data = _read_cookie(cookie_path, True)
                  ^^^^^^^^^^^^^^^^^^^^^^^^^^^^^^^
  File "/home/prx00/spyeyev1/osunt/spyeye/lib/python3.11/site-packages/stem/connection.py", line 1107, in _read_cookie
    raise UnreadableCookieFile(exc_msg, cookie_path, is_safecookie)
stem.connection.UnreadableCookieFile: Authentication failed: unable to read '/run/tor/control.authcookie' ([Errno 13] Permission denied: '/run/tor/control.authcookie')

During handling of the above exception, another exception occurred:

Traceback (most recent call last):
  File "/home/prx00/spyeyev1/osunt/darkweb_monitor.py", line 43, in initialize
    await self._setup_tor()
  File "/home/prx00/spyeyev1/osunt/darkweb_monitor.py", line 96, in _setup_tor
    self.tor_controller.authenticate(password='')
  File "/home/prx00/spyeyev1/osunt/spyeye/lib/python3.11/site-packages/stem/control.py", line 1112, in authenticate
    stem.connection.authenticate(self, *args, **kwargs)
  File "/home/prx00/spyeyev1/osunt/spyeye/lib/python3.11/site-packages/stem/connection.py", line 629, in authenticate
    raise auth_exc
  File "/home/prx00/spyeyev1/osunt/spyeye/lib/python3.11/site-packages/stem/connection.py", line 591, in authenticate
    authenticate_safecookie(controller, cookie_path, False)
  File "/home/prx00/spyeyev1/osunt/spyeye/lib/python3.11/site-packages/stem/connection.py", line 904, in authenticate_safecookie
    cookie_data = _read_cookie(cookie_path, True)
                  ^^^^^^^^^^^^^^^^^^^^^^^^^^^^^^^
  File "/home/prx00/spyeyev1/osunt/spyeye/lib/python3.11/site-packages/stem/connection.py", line 1107, in _read_cookie
    raise UnreadableCookieFile(exc_msg, cookie_path, is_safecookie)
stem.connection.UnreadableCookieFile: Authentication failed: unable to read '/run/tor/control.authcookie' ([Errno 13] Permission denied: '/run/tor/control.authcookie')
2025-03-08 13:05:47,431 - ERROR - Unclosed client session
client_session: <aiohttp.client.ClientSession object at 0x7fa0e6b5a690>
2025-03-08 13:05:47,431 - ERROR - Unclosed client session
client_session: <aiohttp.client.ClientSession object at 0x7fa0e6b5bbd0>
2025-03-08 13:05:47,431 - ERROR - Unclosed client session
client_session: <aiohttp.client.ClientSession object at 0x7fa0e6b5bf10>
2025-03-08 13:05:47,431 - ERROR - Unclosed client session
client_session: <aiohttp.client.ClientSession object at 0x7fa0e5ec74d0>
2025-03-08 13:05:47,429 - ERROR - Failed to load configuration: Expecting value: line 1 column 1 (char 0)
Traceback (most recent call last):
  File "/home/prx00/spyeyev1/osunt/spyeye.py", line 61, in _load_config
    config = json.load(f)
             ^^^^^^^^^^^^
  File "/usr/lib/python3.11/json/__init__.py", line 293, in load
    return loads(fp.read(),
           ^^^^^^^^^^^^^^^^
  File "/usr/lib/python3.11/json/__init__.py", line 346, in loads
    return _default_decoder.decode(s)
           ^^^^^^^^^^^^^^^^^^^^^^^^^^
  File "/usr/lib/python3.11/json/decoder.py", line 337, in decode
    obj, end = self.raw_decode(s, idx=_w(s, 0).end())
               ^^^^^^^^^^^^^^^^^^^^^^^^^^^^^^^^^^^^^^
  File "/usr/lib/python3.11/json/decoder.py", line 355, in raw_decode
    raise JSONDecodeError("Expecting value", s, err.value) from None
json.decoder.JSONDecodeError: Expecting value: line 1 column 1 (char 0)
2025-03-08 13:05:47,432 - ERROR - Unclosed client session
client_session: <aiohttp.client.ClientSession object at 0x7fa0e7ecf010>
