2025-03-08 12:43:22,192 - INFO - API Gatherer initialized successfully
2025-03-08 12:43:22,193 - INFO - Intel X client initialized successfully
2025-03-08 12:43:22,193 - INFO - ====== WebDriver manager ======
2025-03-08 12:43:24,406 - INFO - Get LATEST chromedriver version for google-chrome
2025-03-08 12:43:24,635 - INFO - Get LATEST chromedriver version for google-chrome
2025-03-08 12:43:24,797 - INFO - Driver [C:\Users\derek\.wdm\drivers\chromedriver\win64\133.0.6943.141\chromedriver-win32/chromedriver.exe] found in cache
2025-03-08 12:43:26,662 - INFO - Chrome WebDriver initialized successfully
2025-03-08 12:43:26,663 - INFO - OSINT Gatherer initialized successfully
2025-03-08 12:43:26,668 - ERROR - Failed to setup Tor: Socket error: 0x01: General SOCKS server failure
Traceback (most recent call last):
  File "C:\Users\derek\PycharmProjects\osunt\venv\Lib\site-packages\socks.py", line 809, in connect
    negotiate(self, dest_addr, dest_port)
  File "C:\Users\derek\PycharmProjects\osunt\venv\Lib\site-packages\socks.py", line 443, in _negotiate_SOCKS5
    self.proxy_peername, self.proxy_sockname = self._SOCKS5_request(
                                               ^^^^^^^^^^^^^^^^^^^^^
  File "C:\Users\derek\PycharmProjects\osunt\venv\Lib\site-packages\socks.py", line 533, in _SOCKS5_request
    raise SOCKS5Error("{:#04x}: {}".format(status, error))
socks.SOCKS5Error: 0x01: General SOCKS server failure

During handling of the above exception, another exception occurred:

Traceback (most recent call last):
  File "C:\Users\derek\PycharmProjects\osunt\venv\Lib\site-packages\stem\socket.py", line 535, in _make_socket
    control_socket.connect((self.address, self.port))
  File "C:\Users\derek\PycharmProjects\osunt\venv\Lib\site-packages\socks.py", line 47, in wrapper
    return function(*args, **kwargs)
           ^^^^^^^^^^^^^^^^^^^^^^^^^
  File "C:\Users\derek\PycharmProjects\osunt\venv\Lib\site-packages\socks.py", line 814, in connect
    raise GeneralProxyError("Socket error", error)
socks.GeneralProxyError: Socket error: 0x01: General SOCKS server failure

During handling of the above exception, another exception occurred:

Traceback (most recent call last):
  File "C:\Users\derek\PycharmProjects\osunt\darkweb_monitor.py", line 71, in _setup_tor
    self.tor_controller = Controller.from_port(
                          ^^^^^^^^^^^^^^^^^^^^^
  File "C:\Users\derek\PycharmProjects\osunt\venv\Lib\site-packages\stem\control.py", line 1033, in from_port
    control_port = stem.socket.ControlPort(address, port)
                   ^^^^^^^^^^^^^^^^^^^^^^^^^^^^^^^^^^^^^^
  File "C:\Users\derek\PycharmProjects\osunt\venv\Lib\site-packages\stem\socket.py", line 503, in __init__
    self.connect()
  File "C:\Users\derek\PycharmProjects\osunt\venv\Lib\site-packages\stem\socket.py", line 172, in connect
    self._socket = self._make_socket()
                   ^^^^^^^^^^^^^^^^^^^
  File "C:\Users\derek\PycharmProjects\osunt\venv\Lib\site-packages\stem\socket.py", line 538, in _make_socket
    raise stem.SocketError(exc)
stem.SocketError: Socket error: 0x01: General SOCKS server failure
2025-03-08 12:43:26,673 - ERROR - Failed to initialize Dark Web Monitor: Socket error: 0x01: General SOCKS server failure
Traceback (most recent call last):
  File "C:\Users\derek\PycharmProjects\osunt\venv\Lib\site-packages\socks.py", line 809, in connect
    negotiate(self, dest_addr, dest_port)
  File "C:\Users\derek\PycharmProjects\osunt\venv\Lib\site-packages\socks.py", line 443, in _negotiate_SOCKS5
    self.proxy_peername, self.proxy_sockname = self._SOCKS5_request(
                                               ^^^^^^^^^^^^^^^^^^^^^
  File "C:\Users\derek\PycharmProjects\osunt\venv\Lib\site-packages\socks.py", line 533, in _SOCKS5_request
    raise SOCKS5Error("{:#04x}: {}".format(status, error))
socks.SOCKS5Error: 0x01: General SOCKS server failure

During handling of the above exception, another exception occurred:

Traceback (most recent call last):
  File "C:\Users\derek\PycharmProjects\osunt\venv\Lib\site-packages\stem\socket.py", line 535, in _make_socket
    control_socket.connect((self.address, self.port))
  File "C:\Users\derek\PycharmProjects\osunt\venv\Lib\site-packages\socks.py", line 47, in wrapper
    return function(*args, **kwargs)
           ^^^^^^^^^^^^^^^^^^^^^^^^^
  File "C:\Users\derek\PycharmProjects\osunt\venv\Lib\site-packages\socks.py", line 814, in connect
    raise GeneralProxyError("Socket error", error)
socks.GeneralProxyError: Socket error: 0x01: General SOCKS server failure

During handling of the above exception, another exception occurred:

Traceback (most recent call last):
  File "C:\Users\derek\PycharmProjects\osunt\darkweb_monitor.py", line 43, in initialize
    await self._setup_tor()
  File "C:\Users\derek\PycharmProjects\osunt\darkweb_monitor.py", line 71, in _setup_tor
    self.tor_controller = Controller.from_port(
                          ^^^^^^^^^^^^^^^^^^^^^
  File "C:\Users\derek\PycharmProjects\osunt\venv\Lib\site-packages\stem\control.py", line 1033, in from_port
    control_port = stem.socket.ControlPort(address, port)
                   ^^^^^^^^^^^^^^^^^^^^^^^^^^^^^^^^^^^^^^
  File "C:\Users\derek\PycharmProjects\osunt\venv\Lib\site-packages\stem\socket.py", line 503, in __init__
    self.connect()
  File "C:\Users\derek\PycharmProjects\osunt\venv\Lib\site-packages\stem\socket.py", line 172, in connect
    self._socket = self._make_socket()
                   ^^^^^^^^^^^^^^^^^^^
  File "C:\Users\derek\PycharmProjects\osunt\venv\Lib\site-packages\stem\socket.py", line 538, in _make_socket
    raise stem.SocketError(exc)
stem.SocketError: Socket error: 0x01: General SOCKS server failure
2025-03-08 12:43:26,677 - ERROR - Unclosed client session
client_session: <aiohttp.client.ClientSession object at 0x000001DD093ACD50>
2025-03-08 12:43:26,677 - ERROR - Unclosed client session
client_session: <aiohttp.client.ClientSession object at 0x000001DD06DF8610>
2025-03-08 12:43:26,677 - ERROR - Unclosed client session
client_session: <aiohttp.client.ClientSession object at 0x000001DD07127110>
2025-03-08 12:43:26,678 - ERROR - Unclosed client session
client_session: <aiohttp.client.ClientSession object at 0x000001DD073E8F10>
2025-03-08 12:43:26,678 - ERROR - Failed to load configuration: Expecting value: line 1 column 1 (char 0)
Traceback (most recent call last):
  File "C:\Users\derek\PycharmProjects\osunt\spyeye.py", line 61, in _load_config
    config = json.load(f)
             ^^^^^^^^^^^^
  File "C:\Program Files\WindowsApps\PythonSoftwareFoundation.Python.3.11_3.11.2544.0_x64__qbz5n2kfra8p0\Lib\json\__init__.py", line 293, in load
    return loads(fp.read(),
           ^^^^^^^^^^^^^^^^
  File "C:\Program Files\WindowsApps\PythonSoftwareFoundation.Python.3.11_3.11.2544.0_x64__qbz5n2kfra8p0\Lib\json\__init__.py", line 346, in loads
    return _default_decoder.decode(s)
           ^^^^^^^^^^^^^^^^^^^^^^^^^^
  File "C:\Program Files\WindowsApps\PythonSoftwareFoundation.Python.3.11_3.11.2544.0_x64__qbz5n2kfra8p0\Lib\json\decoder.py", line 337, in decode
    obj, end = self.raw_decode(s, idx=_w(s, 0).end())
               ^^^^^^^^^^^^^^^^^^^^^^^^^^^^^^^^^^^^^^
  File "C:\Program Files\WindowsApps\PythonSoftwareFoundation.Python.3.11_3.11.2544.0_x64__qbz5n2kfra8p0\Lib\json\decoder.py", line 355, in raw_decode
    raise JSONDecodeError("Expecting value", s, err.value) from None
json.decoder.JSONDecodeError: Expecting value: line 1 column 1 (char 0)
2025-03-08 12:43:26,683 - ERROR - Unclosed client session
client_session: <aiohttp.client.ClientSession object at 0x000001DD07127110>
